ERROR 2024-09-21 10:09:30,538 forms Error saving meeting: name 'send_follow_up_email' is not defined
ERROR 2024-09-22 10:04:59,299 log Internal Server Error: /agent_support/add_agent_supplier/
Traceback (most recent call last):
  File "/workspace/.pip-modules/lib/python3.12/site-packages/django/core/handlers/exception.py", line 55, in inner
    response = get_response(request)
               ^^^^^^^^^^^^^^^^^^^^^
  File "/workspace/.pip-modules/lib/python3.12/site-packages/django/core/handlers/base.py", line 197, in _get_response
    response = wrapped_callback(request, *callback_args, **callback_kwargs)
               ^^^^^^^^^^^^^^^^^^^^^^^^^^^^^^^^^^^^^^^^^^^^^^^^^^^^^^^^^^^^
  File "/workspace/.pip-modules/lib/python3.12/site-packages/django/contrib/auth/decorators.py", line 60, in _view_wrapper
    return view_func(request, *args, **kwargs)
           ^^^^^^^^^^^^^^^^^^^^^^^^^^^^^^^^^^^
  File "/workspace/travault-v2-mp4/travault_crm/agent_support/views.py", line 67, in add_agent_supplier
    logger.info(f"New agent supplier '{supplier.name}' added for agency '{agency.name}'.")
                                       ^^^^^^^^^^^^^
AttributeError: 'AgentSupportSupplier' object has no attribute 'name'
ERROR 2024-09-22 10:04:59,301 basehttp "POST /agent_support/add_agent_supplier/ HTTP/1.1" 500 91432
ERROR 2024-09-22 10:10:30,777 log Internal Server Error: /agent_support/add_agent_supplier/
Traceback (most recent call last):
  File "/workspace/.pip-modules/lib/python3.12/site-packages/django/core/handlers/exception.py", line 55, in inner
    response = get_response(request)
               ^^^^^^^^^^^^^^^^^^^^^
  File "/workspace/.pip-modules/lib/python3.12/site-packages/django/core/handlers/base.py", line 197, in _get_response
    response = wrapped_callback(request, *callback_args, **callback_kwargs)
               ^^^^^^^^^^^^^^^^^^^^^^^^^^^^^^^^^^^^^^^^^^^^^^^^^^^^^^^^^^^^
  File "/workspace/.pip-modules/lib/python3.12/site-packages/django/contrib/auth/decorators.py", line 60, in _view_wrapper
    return view_func(request, *args, **kwargs)
           ^^^^^^^^^^^^^^^^^^^^^^^^^^^^^^^^^^^
  File "/workspace/travault-v2-mp4/travault_crm/agent_support/views.py", line 67, in add_agent_supplier
    logger.info(f"New agent supplier '{supplier.name}' added for agency '{agency.name}'.")
                                       ^^^^^^^^^^^^^
AttributeError: 'AgentSupportSupplier' object has no attribute 'name'
ERROR 2024-09-22 10:10:30,779 basehttp "POST /agent_support/add_agent_supplier/ HTTP/1.1" 500 91432
ERROR 2024-09-23 06:18:58,413 log Internal Server Error: /activity/meeting/4/delete/
Traceback (most recent call last):
  File "/workspace/.pip-modules/lib/python3.12/site-packages/django/core/handlers/exception.py", line 55, in inner
    response = get_response(request)
               ^^^^^^^^^^^^^^^^^^^^^
  File "/workspace/.pip-modules/lib/python3.12/site-packages/django/core/handlers/base.py", line 204, in _get_response
    self.check_response(response, callback)
  File "/workspace/.pip-modules/lib/python3.12/site-packages/django/core/handlers/base.py", line 332, in check_response
    raise ValueError(
ValueError: The view activity_log.views.delete_meeting didn't return an HttpResponse object. It returned None instead.
ERROR 2024-09-23 06:18:58,414 basehttp "GET /activity/meeting/4/delete/ HTTP/1.1" 500 81767
ERROR 2024-09-23 06:19:30,804 log Internal Server Error: /activity/meeting/4/delete/
Traceback (most recent call last):
  File "/workspace/.pip-modules/lib/python3.12/site-packages/django/core/handlers/exception.py", line 55, in inner
    response = get_response(request)
               ^^^^^^^^^^^^^^^^^^^^^
  File "/workspace/.pip-modules/lib/python3.12/site-packages/django/core/handlers/base.py", line 204, in _get_response
    self.check_response(response, callback)
  File "/workspace/.pip-modules/lib/python3.12/site-packages/django/core/handlers/base.py", line 332, in check_response
    raise ValueError(
ValueError: The view activity_log.views.delete_meeting didn't return an HttpResponse object. It returned None instead.
ERROR 2024-09-23 06:19:30,805 basehttp "GET /activity/meeting/4/delete/ HTTP/1.1" 500 81904
ERROR 2024-09-23 06:23:19,711 log Internal Server Error: /activity/meeting/7/delete/
Traceback (most recent call last):
  File "/workspace/.pip-modules/lib/python3.12/site-packages/django/core/handlers/exception.py", line 55, in inner
    response = get_response(request)
               ^^^^^^^^^^^^^^^^^^^^^
  File "/workspace/.pip-modules/lib/python3.12/site-packages/django/core/handlers/base.py", line 197, in _get_response
    response = wrapped_callback(request, *callback_args, **callback_kwargs)
               ^^^^^^^^^^^^^^^^^^^^^^^^^^^^^^^^^^^^^^^^^^^^^^^^^^^^^^^^^^^^
  File "/workspace/.pip-modules/lib/python3.12/site-packages/django/contrib/auth/decorators.py", line 60, in _view_wrapper
    return view_func(request, *args, **kwargs)
           ^^^^^^^^^^^^^^^^^^^^^^^^^^^^^^^^^^^
  File "/workspace/travault-v2-mp4/travault_crm/activity_log/views.py", line 112, in delete_meeting
    return render(request, 'activity_log/confirm_delete.html', context)
           ^^^^^^^^^^^^^^^^^^^^^^^^^^^^^^^^^^^^^^^^^^^^^^^^^^^^^^^^^^^^
  File "/workspace/.pip-modules/lib/python3.12/site-packages/django/shortcuts.py", line 25, in render
    content = loader.render_to_string(template_name, context, request, using=using)
              ^^^^^^^^^^^^^^^^^^^^^^^^^^^^^^^^^^^^^^^^^^^^^^^^^^^^^^^^^^^^^^^^^^^^^
  File "/workspace/.pip-modules/lib/python3.12/site-packages/django/template/loader.py", line 62, in render_to_string
    return template.render(context, request)
           ^^^^^^^^^^^^^^^^^^^^^^^^^^^^^^^^^
  File "/workspace/.pip-modules/lib/python3.12/site-packages/django/template/backends/django.py", line 107, in render
    return self.template.render(context)
           ^^^^^^^^^^^^^^^^^^^^^^^^^^^^^
  File "/workspace/.pip-modules/lib/python3.12/site-packages/django/template/base.py", line 171, in render
    return self._render(context)
           ^^^^^^^^^^^^^^^^^^^^^
  File "/workspace/.pip-modules/lib/python3.12/site-packages/django/template/base.py", line 163, in _render
    return self.nodelist.render(context)
           ^^^^^^^^^^^^^^^^^^^^^^^^^^^^^
  File "/workspace/.pip-modules/lib/python3.12/site-packages/django/template/base.py", line 1008, in render
    return SafeString("".join([node.render_annotated(context) for node in self]))
                               ^^^^^^^^^^^^^^^^^^^^^^^^^^^^^^
  File "/workspace/.pip-modules/lib/python3.12/site-packages/django/template/base.py", line 969, in render_annotated
    return self.render(context)
           ^^^^^^^^^^^^^^^^^^^^
  File "/workspace/.pip-modules/lib/python3.12/site-packages/django/template/loader_tags.py", line 159, in render
    return compiled_parent._render(context)
           ^^^^^^^^^^^^^^^^^^^^^^^^^^^^^^^^
  File "/workspace/.pip-modules/lib/python3.12/site-packages/django/template/base.py", line 163, in _render
    return self.nodelist.render(context)
           ^^^^^^^^^^^^^^^^^^^^^^^^^^^^^
  File "/workspace/.pip-modules/lib/python3.12/site-packages/django/template/base.py", line 1008, in render
    return SafeString("".join([node.render_annotated(context) for node in self]))
                               ^^^^^^^^^^^^^^^^^^^^^^^^^^^^^^
  File "/workspace/.pip-modules/lib/python3.12/site-packages/django/template/base.py", line 969, in render_annotated
    return self.render(context)
           ^^^^^^^^^^^^^^^^^^^^
  File "/workspace/.pip-modules/lib/python3.12/site-packages/django/template/loader_tags.py", line 65, in render
    result = block.nodelist.render(context)
             ^^^^^^^^^^^^^^^^^^^^^^^^^^^^^^
  File "/workspace/.pip-modules/lib/python3.12/site-packages/django/template/base.py", line 1008, in render
    return SafeString("".join([node.render_annotated(context) for node in self]))
                               ^^^^^^^^^^^^^^^^^^^^^^^^^^^^^^
  File "/workspace/.pip-modules/lib/python3.12/site-packages/django/template/base.py", line 969, in render_annotated
    return self.render(context)
           ^^^^^^^^^^^^^^^^^^^^
  File "/workspace/.pip-modules/lib/python3.12/site-packages/django/template/defaulttags.py", line 480, in render
    url = reverse(view_name, args=args, kwargs=kwargs, current_app=current_app)
          ^^^^^^^^^^^^^^^^^^^^^^^^^^^^^^^^^^^^^^^^^^^^^^^^^^^^^^^^^^^^^^^^^^^^^
  File "/workspace/.pip-modules/lib/python3.12/site-packages/django/urls/base.py", line 88, in reverse
    return resolver._reverse_with_prefix(view, prefix, *args, **kwargs)
           ^^^^^^^^^^^^^^^^^^^^^^^^^^^^^^^^^^^^^^^^^^^^^^^^^^^^^^^^^^^^
  File "/workspace/.pip-modules/lib/python3.12/site-packages/django/urls/resolvers.py", line 831, in _reverse_with_prefix
    raise NoReverseMatch(msg)
django.urls.exceptions.NoReverseMatch: Reverse for 'company_detail_with_tab' with keyword arguments '{'pk': '', 'active_tab': 'activity'}' not found. 1 pattern(s) tried: ['crm/company/(?P<pk>[0-9]+)/(?P<active_tab>[^/]+)/\\Z']
ERROR 2024-09-23 06:23:19,714 basehttp "GET /activity/meeting/7/delete/ HTTP/1.1" 500 181312
ERROR 2024-09-23 06:42:08,292 log Internal Server Error: /activity/meeting/7/delete/
Traceback (most recent call last):
  File "/workspace/.pip-modules/lib/python3.12/site-packages/django/core/handlers/exception.py", line 55, in inner
    response = get_response(request)
               ^^^^^^^^^^^^^^^^^^^^^
  File "/workspace/.pip-modules/lib/python3.12/site-packages/django/core/handlers/base.py", line 197, in _get_response
    response = wrapped_callback(request, *callback_args, **callback_kwargs)
               ^^^^^^^^^^^^^^^^^^^^^^^^^^^^^^^^^^^^^^^^^^^^^^^^^^^^^^^^^^^^
  File "/workspace/.pip-modules/lib/python3.12/site-packages/django/contrib/auth/decorators.py", line 60, in _view_wrapper
    return view_func(request, *args, **kwargs)
           ^^^^^^^^^^^^^^^^^^^^^^^^^^^^^^^^^^^
  File "/workspace/travault-v2-mp4/travault_crm/activity_log/views.py", line 126, in delete_meeting
    base_url = reverse('crm:company_detail_with_tab', kwargs={'pk': company.pk})
               ^^^^^^^
NameError: name 'reverse' is not defined. Did you mean: 'reversed'?
ERROR 2024-09-23 06:42:08,295 basehttp "POST /activity/meeting/7/delete/ HTTP/1.1" 500 87678
ERROR 2024-09-23 06:45:23,995 log Internal Server Error: /activity/meeting/7/delete/
Traceback (most recent call last):
  File "/workspace/.pip-modules/lib/python3.12/site-packages/django/core/handlers/exception.py", line 55, in inner
    response = get_response(request)
               ^^^^^^^^^^^^^^^^^^^^^
  File "/workspace/.pip-modules/lib/python3.12/site-packages/django/core/handlers/base.py", line 197, in _get_response
    response = wrapped_callback(request, *callback_args, **callback_kwargs)
               ^^^^^^^^^^^^^^^^^^^^^^^^^^^^^^^^^^^^^^^^^^^^^^^^^^^^^^^^^^^^
  File "/workspace/.pip-modules/lib/python3.12/site-packages/django/contrib/auth/decorators.py", line 60, in _view_wrapper
    return view_func(request, *args, **kwargs)
           ^^^^^^^^^^^^^^^^^^^^^^^^^^^^^^^^^^^
  File "/workspace/travault-v2-mp4/travault_crm/activity_log/views.py", line 95, in delete_meeting
    meeting = get_object_or_404(Meeting, pk=pk, is_deleted=False)  # Adjust for soft deletion if implemented
              ^^^^^^^^^^^^^^^^^^^^^^^^^^^^^^^^^^^^^^^^^^^^^^^^^^^
  File "/workspace/.pip-modules/lib/python3.12/site-packages/django/shortcuts.py", line 86, in get_object_or_404
    return queryset.get(*args, **kwargs)
           ^^^^^^^^^^^^^^^^^^^^^^^^^^^^^
  File "/workspace/.pip-modules/lib/python3.12/site-packages/django/db/models/query.py", line 635, in get
    clone = self._chain() if self.query.combinator else self.filter(*args, **kwargs)
                                                        ^^^^^^^^^^^^^^^^^^^^^^^^^^^^
  File "/workspace/.pip-modules/lib/python3.12/site-packages/django/db/models/query.py", line 1476, in filter
    return self._filter_or_exclude(False, args, kwargs)
           ^^^^^^^^^^^^^^^^^^^^^^^^^^^^^^^^^^^^^^^^^^^^
  File "/workspace/.pip-modules/lib/python3.12/site-packages/django/db/models/query.py", line 1494, in _filter_or_exclude
    clone._filter_or_exclude_inplace(negate, args, kwargs)
  File "/workspace/.pip-modules/lib/python3.12/site-packages/django/db/models/query.py", line 1501, in _filter_or_exclude_inplace
    self._query.add_q(Q(*args, **kwargs))
  File "/workspace/.pip-modules/lib/python3.12/site-packages/django/db/models/sql/query.py", line 1609, in add_q
    clause, _ = self._add_q(q_object, self.used_aliases)
                ^^^^^^^^^^^^^^^^^^^^^^^^^^^^^^^^^^^^^^^^
  File "/workspace/.pip-modules/lib/python3.12/site-packages/django/db/models/sql/query.py", line 1641, in _add_q
    child_clause, needed_inner = self.build_filter(
                                 ^^^^^^^^^^^^^^^^^^
  File "/workspace/.pip-modules/lib/python3.12/site-packages/django/db/models/sql/query.py", line 1491, in build_filter
    lookups, parts, reffed_expression = self.solve_lookup_type(arg, summarize)
                                        ^^^^^^^^^^^^^^^^^^^^^^^^^^^^^^^^^^^^^^
  File "/workspace/.pip-modules/lib/python3.12/site-packages/django/db/models/sql/query.py", line 1303, in solve_lookup_type
    _, field, _, lookup_parts = self.names_to_path(lookup_splitted, self.get_meta())
                                ^^^^^^^^^^^^^^^^^^^^^^^^^^^^^^^^^^^^^^^^^^^^^^^^^^^^
  File "/workspace/.pip-modules/lib/python3.12/site-packages/django/db/models/sql/query.py", line 1768, in names_to_path
    raise FieldError(
django.core.exceptions.FieldError: Cannot resolve keyword 'is_deleted' into field. Choices are: attendees, company, company_contacts, company_id, created_at, creator, creator_id, date, details, duration, id, location, outcome, subject, time, to_do_task_date, to_do_task_message, updated_at
ERROR 2024-09-23 06:45:23,997 basehttp "POST /activity/meeting/7/delete/ HTTP/1.1" 500 139824
ERROR 2024-09-23 06:48:20,998 log Internal Server Error: /activity/meeting/5/delete/
Traceback (most recent call last):
  File "/workspace/.pip-modules/lib/python3.12/site-packages/django/core/handlers/exception.py", line 55, in inner
    response = get_response(request)
               ^^^^^^^^^^^^^^^^^^^^^
  File "/workspace/.pip-modules/lib/python3.12/site-packages/django/core/handlers/base.py", line 197, in _get_response
    response = wrapped_callback(request, *callback_args, **callback_kwargs)
               ^^^^^^^^^^^^^^^^^^^^^^^^^^^^^^^^^^^^^^^^^^^^^^^^^^^^^^^^^^^^
  File "/workspace/.pip-modules/lib/python3.12/site-packages/django/contrib/auth/decorators.py", line 60, in _view_wrapper
    return view_func(request, *args, **kwargs)
           ^^^^^^^^^^^^^^^^^^^^^^^^^^^^^^^^^^^
  File "/workspace/travault-v2-mp4/travault_crm/activity_log/views.py", line 129, in delete_meeting
    return render(request, 'activity_log/confirm_delete.html', context)
           ^^^^^^^^^^^^^^^^^^^^^^^^^^^^^^^^^^^^^^^^^^^^^^^^^^^^^^^^^^^^
  File "/workspace/.pip-modules/lib/python3.12/site-packages/django/shortcuts.py", line 25, in render
    content = loader.render_to_string(template_name, context, request, using=using)
              ^^^^^^^^^^^^^^^^^^^^^^^^^^^^^^^^^^^^^^^^^^^^^^^^^^^^^^^^^^^^^^^^^^^^^
  File "/workspace/.pip-modules/lib/python3.12/site-packages/django/template/loader.py", line 62, in render_to_string
    return template.render(context, request)
           ^^^^^^^^^^^^^^^^^^^^^^^^^^^^^^^^^
  File "/workspace/.pip-modules/lib/python3.12/site-packages/django/template/backends/django.py", line 107, in render
    return self.template.render(context)
           ^^^^^^^^^^^^^^^^^^^^^^^^^^^^^
  File "/workspace/.pip-modules/lib/python3.12/site-packages/django/template/base.py", line 171, in render
    return self._render(context)
           ^^^^^^^^^^^^^^^^^^^^^
  File "/workspace/.pip-modules/lib/python3.12/site-packages/django/template/base.py", line 163, in _render
    return self.nodelist.render(context)
           ^^^^^^^^^^^^^^^^^^^^^^^^^^^^^
  File "/workspace/.pip-modules/lib/python3.12/site-packages/django/template/base.py", line 1008, in render
    return SafeString("".join([node.render_annotated(context) for node in self]))
                               ^^^^^^^^^^^^^^^^^^^^^^^^^^^^^^
  File "/workspace/.pip-modules/lib/python3.12/site-packages/django/template/base.py", line 969, in render_annotated
    return self.render(context)
           ^^^^^^^^^^^^^^^^^^^^
  File "/workspace/.pip-modules/lib/python3.12/site-packages/django/template/loader_tags.py", line 159, in render
    return compiled_parent._render(context)
           ^^^^^^^^^^^^^^^^^^^^^^^^^^^^^^^^
  File "/workspace/.pip-modules/lib/python3.12/site-packages/django/template/base.py", line 163, in _render
    return self.nodelist.render(context)
           ^^^^^^^^^^^^^^^^^^^^^^^^^^^^^
  File "/workspace/.pip-modules/lib/python3.12/site-packages/django/template/base.py", line 1008, in render
    return SafeString("".join([node.render_annotated(context) for node in self]))
                               ^^^^^^^^^^^^^^^^^^^^^^^^^^^^^^
  File "/workspace/.pip-modules/lib/python3.12/site-packages/django/template/base.py", line 969, in render_annotated
    return self.render(context)
           ^^^^^^^^^^^^^^^^^^^^
  File "/workspace/.pip-modules/lib/python3.12/site-packages/django/template/loader_tags.py", line 65, in render
    result = block.nodelist.render(context)
             ^^^^^^^^^^^^^^^^^^^^^^^^^^^^^^
  File "/workspace/.pip-modules/lib/python3.12/site-packages/django/template/base.py", line 1008, in render
    return SafeString("".join([node.render_annotated(context) for node in self]))
                               ^^^^^^^^^^^^^^^^^^^^^^^^^^^^^^
  File "/workspace/.pip-modules/lib/python3.12/site-packages/django/template/base.py", line 969, in render_annotated
    return self.render(context)
           ^^^^^^^^^^^^^^^^^^^^
  File "/workspace/.pip-modules/lib/python3.12/site-packages/django/template/defaulttags.py", line 480, in render
    url = reverse(view_name, args=args, kwargs=kwargs, current_app=current_app)
          ^^^^^^^^^^^^^^^^^^^^^^^^^^^^^^^^^^^^^^^^^^^^^^^^^^^^^^^^^^^^^^^^^^^^^
  File "/workspace/.pip-modules/lib/python3.12/site-packages/django/urls/base.py", line 88, in reverse
    return resolver._reverse_with_prefix(view, prefix, *args, **kwargs)
           ^^^^^^^^^^^^^^^^^^^^^^^^^^^^^^^^^^^^^^^^^^^^^^^^^^^^^^^^^^^^
  File "/workspace/.pip-modules/lib/python3.12/site-packages/django/urls/resolvers.py", line 831, in _reverse_with_prefix
    raise NoReverseMatch(msg)
django.urls.exceptions.NoReverseMatch: Reverse for 'company_detail_with_tab' with keyword arguments '{'pk': 1}' not found. 1 pattern(s) tried: ['crm/company/(?P<pk>[0-9]+)/(?P<active_tab>[^/]+)/\\Z']
ERROR 2024-09-23 06:48:21,000 basehttp "GET /activity/meeting/5/delete/ HTTP/1.1" 500 180089
ERROR 2024-09-23 06:49:31,945 log Internal Server Error: /activity/meeting/5/delete/
Traceback (most recent call last):
  File "/workspace/.pip-modules/lib/python3.12/site-packages/django/core/handlers/exception.py", line 55, in inner
    response = get_response(request)
               ^^^^^^^^^^^^^^^^^^^^^
  File "/workspace/.pip-modules/lib/python3.12/site-packages/django/core/handlers/base.py", line 197, in _get_response
    response = wrapped_callback(request, *callback_args, **callback_kwargs)
               ^^^^^^^^^^^^^^^^^^^^^^^^^^^^^^^^^^^^^^^^^^^^^^^^^^^^^^^^^^^^
  File "/workspace/.pip-modules/lib/python3.12/site-packages/django/contrib/auth/decorators.py", line 60, in _view_wrapper
    return view_func(request, *args, **kwargs)
           ^^^^^^^^^^^^^^^^^^^^^^^^^^^^^^^^^^^
  File "/workspace/travault-v2-mp4/travault_crm/activity_log/views.py", line 119, in delete_meeting
    base_url = reverse('crm:company_detail_with_tab', kwargs={'pk': company.pk})
               ^^^^^^^
NameError: name 'reverse' is not defined. Did you mean: 'reversed'?
ERROR 2024-09-23 06:49:31,947 basehttp "POST /activity/meeting/5/delete/ HTTP/1.1" 500 87659
